[2024-11-18T23:38:56.368+0000] {taskinstance.py:1979} INFO - Dependencies all met for dep_context=non-requeueable deps ti=<TaskInstance: python_broker.sensor manual__2024-11-18T23:38:53.823654+00:00 [queued]>
[2024-11-18T23:38:56.387+0000] {taskinstance.py:1979} INFO - Dependencies all met for dep_context=requeueable deps ti=<TaskInstance: python_broker.sensor manual__2024-11-18T23:38:53.823654+00:00 [queued]>
[2024-11-18T23:38:56.388+0000] {taskinstance.py:2193} INFO - Starting attempt 1 of 1
[2024-11-18T23:38:56.418+0000] {taskinstance.py:2217} INFO - Executing <Task(RabbitMQSensor): sensor> on 2024-11-18 23:38:53.823654+00:00
[2024-11-18T23:38:56.428+0000] {standard_task_runner.py:60} INFO - Started process 186 to run task
[2024-11-18T23:38:56.433+0000] {standard_task_runner.py:87} INFO - Running: ['***', 'tasks', 'run', 'python_broker', 'sensor', 'manual__2024-11-18T23:38:53.823654+00:00', '--job-id', '15', '--raw', '--subdir', 'DAGS_FOLDER/python_broker.py', '--cfg-path', '/tmp/tmp67pmo117']
[2024-11-18T23:38:56.435+0000] {standard_task_runner.py:88} INFO - Job 15: Subtask sensor
[2024-11-18T23:38:56.511+0000] {task_command.py:423} INFO - Running <TaskInstance: python_broker.sensor manual__2024-11-18T23:38:53.823654+00:00 [running]> on host e8cb2db159e8
[2024-11-18T23:38:56.638+0000] {taskinstance.py:2513} INFO - Exporting env vars: AIRFLOW_CTX_DAG_OWNER='***' AIRFLOW_CTX_DAG_ID='python_broker' AIRFLOW_CTX_TASK_ID='sensor' AIRFLOW_CTX_EXECUTION_DATE='2024-11-18T23:38:53.823654+00:00' AIRFLOW_CTX_TRY_NUMBER='1' AIRFLOW_CTX_DAG_RUN_ID='manual__2024-11-18T23:38:53.823654+00:00'
[2024-11-18T23:38:56.653+0000] {base.py:83} INFO - Using connection ID 'RabbitMQ' for task execution.
[2024-11-18T23:38:56.655+0000] {taskinstance.py:2731} ERROR - Task failed with exception
Traceback (most recent call last):
  File "/home/airflow/.local/lib/python3.8/site-packages/pika/connection.py", line 389, in port
    self._port = int(value)
TypeError: int() argument must be a string, a bytes-like object or a number, not 'NoneType'

During handling of the above exception, another exception occurred:

Traceback (most recent call last):
  File "/home/airflow/.local/lib/python3.8/site-packages/airflow/models/taskinstance.py", line 444, in _execute_task
    result = _execute_callable(context=context, **execute_callable_kwargs)
  File "/home/airflow/.local/lib/python3.8/site-packages/airflow/models/taskinstance.py", line 414, in _execute_callable
    return execute_callable(context=context, **execute_callable_kwargs)
  File "/home/airflow/.local/lib/python3.8/site-packages/rabbitmq_provider/sensors/rabbitmq.py", line 32, in execute
    super().execute(context)
  File "/home/airflow/.local/lib/python3.8/site-packages/airflow/sensors/base.py", line 265, in execute
    raise e
  File "/home/airflow/.local/lib/python3.8/site-packages/airflow/sensors/base.py", line 247, in execute
    poke_return = self.poke(context)
  File "/home/airflow/.local/lib/python3.8/site-packages/rabbitmq_provider/sensors/rabbitmq.py", line 37, in poke
    message = hook.pull(self.queue_name)
  File "/home/airflow/.local/lib/python3.8/site-packages/rabbitmq_provider/hooks/rabbitmq.py", line 123, in pull
    connection = self.get_conn()
  File "/home/airflow/.local/lib/python3.8/site-packages/rabbitmq_provider/hooks/rabbitmq.py", line 53, in get_conn
    parameters = pika.ConnectionParameters(
  File "/home/airflow/.local/lib/python3.8/site-packages/pika/connection.py", line 645, in __init__
    self.port = port
  File "/home/airflow/.local/lib/python3.8/site-packages/pika/connection.py", line 391, in port
    raise TypeError('port must be an int, but got %r' % (value,))
TypeError: port must be an int, but got None
[2024-11-18T23:38:56.669+0000] {taskinstance.py:1149} INFO - Marking task as FAILED. dag_id=python_broker, task_id=sensor, execution_date=20241118T233853, start_date=20241118T233856, end_date=20241118T233856
[2024-11-18T23:38:56.686+0000] {standard_task_runner.py:107} ERROR - Failed to execute job 15 for task sensor (port must be an int, but got None; 186)
[2024-11-18T23:38:56.727+0000] {local_task_job_runner.py:234} INFO - Task exited with return code 1
[2024-11-18T23:38:56.766+0000] {taskinstance.py:3312} INFO - 0 downstream tasks scheduled from follow-on schedule check
