[2024-11-18T23:16:42.483+0000] {taskinstance.py:1979} INFO - Dependencies all met for dep_context=non-requeueable deps ti=<TaskInstance: python_broker.sensor manual__2024-11-18T23:16:34.204663+00:00 [queued]>
[2024-11-18T23:16:42.531+0000] {taskinstance.py:1979} INFO - Dependencies all met for dep_context=requeueable deps ti=<TaskInstance: python_broker.sensor manual__2024-11-18T23:16:34.204663+00:00 [queued]>
[2024-11-18T23:16:42.532+0000] {taskinstance.py:2193} INFO - Starting attempt 1 of 1
[2024-11-18T23:16:42.611+0000] {taskinstance.py:2217} INFO - Executing <Task(RabbitMQSensor): sensor> on 2024-11-18 23:16:34.204663+00:00
[2024-11-18T23:16:42.638+0000] {standard_task_runner.py:60} INFO - Started process 253 to run task
[2024-11-18T23:16:42.649+0000] {standard_task_runner.py:87} INFO - Running: ['***', 'tasks', 'run', 'python_broker', 'sensor', 'manual__2024-11-18T23:16:34.204663+00:00', '--job-id', '10', '--raw', '--subdir', 'DAGS_FOLDER/python_broker.py', '--cfg-path', '/tmp/tmpgqxhfe2t']
[2024-11-18T23:16:42.653+0000] {standard_task_runner.py:88} INFO - Job 10: Subtask sensor
[2024-11-18T23:16:42.780+0000] {task_command.py:423} INFO - Running <TaskInstance: python_broker.sensor manual__2024-11-18T23:16:34.204663+00:00 [running]> on host e8cb2db159e8
[2024-11-18T23:16:43.043+0000] {taskinstance.py:2513} INFO - Exporting env vars: AIRFLOW_CTX_DAG_OWNER='***' AIRFLOW_CTX_DAG_ID='python_broker' AIRFLOW_CTX_TASK_ID='sensor' AIRFLOW_CTX_EXECUTION_DATE='2024-11-18T23:16:34.204663+00:00' AIRFLOW_CTX_TRY_NUMBER='1' AIRFLOW_CTX_DAG_RUN_ID='manual__2024-11-18T23:16:34.204663+00:00'
[2024-11-18T23:16:43.099+0000] {taskinstance.py:2731} ERROR - Task failed with exception
Traceback (most recent call last):
  File "/home/airflow/.local/lib/python3.8/site-packages/airflow/models/taskinstance.py", line 444, in _execute_task
    result = _execute_callable(context=context, **execute_callable_kwargs)
  File "/home/airflow/.local/lib/python3.8/site-packages/airflow/models/taskinstance.py", line 414, in _execute_callable
    return execute_callable(context=context, **execute_callable_kwargs)
  File "/home/airflow/.local/lib/python3.8/site-packages/rabbitmq_provider/sensors/rabbitmq.py", line 32, in execute
    super().execute(context)
  File "/home/airflow/.local/lib/python3.8/site-packages/airflow/sensors/base.py", line 265, in execute
    raise e
  File "/home/airflow/.local/lib/python3.8/site-packages/airflow/sensors/base.py", line 247, in execute
    poke_return = self.poke(context)
  File "/home/airflow/.local/lib/python3.8/site-packages/rabbitmq_provider/sensors/rabbitmq.py", line 37, in poke
    message = hook.pull(self.queue_name)
  File "/home/airflow/.local/lib/python3.8/site-packages/rabbitmq_provider/hooks/rabbitmq.py", line 123, in pull
    connection = self.get_conn()
  File "/home/airflow/.local/lib/python3.8/site-packages/rabbitmq_provider/hooks/rabbitmq.py", line 48, in get_conn
    conn = self.get_connection(self.rabbitmq_conn_id)
  File "/home/airflow/.local/lib/python3.8/site-packages/airflow/hooks/base.py", line 82, in get_connection
    conn = Connection.get_connection_from_secrets(conn_id)
  File "/home/airflow/.local/lib/python3.8/site-packages/airflow/models/connection.py", line 514, in get_connection_from_secrets
    raise AirflowNotFoundException(f"The conn_id `{conn_id}` isn't defined")
airflow.exceptions.AirflowNotFoundException: The conn_id `RabbitMQ` isn't defined
[2024-11-18T23:16:43.117+0000] {taskinstance.py:1149} INFO - Marking task as FAILED. dag_id=python_broker, task_id=sensor, execution_date=20241118T231634, start_date=20241118T231642, end_date=20241118T231643
[2024-11-18T23:16:43.158+0000] {standard_task_runner.py:107} ERROR - Failed to execute job 10 for task sensor (The conn_id `RabbitMQ` isn't defined; 253)
[2024-11-18T23:16:43.213+0000] {local_task_job_runner.py:234} INFO - Task exited with return code 1
[2024-11-18T23:16:43.310+0000] {taskinstance.py:3312} INFO - 0 downstream tasks scheduled from follow-on schedule check
